[2025-03-24T12:04:10.413+0000] {taskinstance.py:1956} INFO - Dependencies all met for dep_context=non-requeueable deps ti=<TaskInstance: data_service.reset_data manual__2025-03-24T12:04:06.950635+00:00 [queued]>
[2025-03-24T12:04:10.423+0000] {taskinstance.py:1956} INFO - Dependencies all met for dep_context=requeueable deps ti=<TaskInstance: data_service.reset_data manual__2025-03-24T12:04:06.950635+00:00 [queued]>
[2025-03-24T12:04:10.424+0000] {taskinstance.py:2170} INFO - Starting attempt 1 of 1
[2025-03-24T12:04:10.438+0000] {taskinstance.py:2191} INFO - Executing <Task(DockerOperator): reset_data> on 2025-03-24 12:04:06.950635+00:00
[2025-03-24T12:04:10.445+0000] {standard_task_runner.py:60} INFO - Started process 1687 to run task
[2025-03-24T12:04:10.448+0000] {standard_task_runner.py:87} INFO - Running: ['***', 'tasks', 'run', 'data_service', 'reset_data', 'manual__2025-03-24T12:04:06.950635+00:00', '--job-id', '66', '--raw', '--subdir', 'DAGS_FOLDER/data_service_dag.py', '--cfg-path', '/tmp/tmptivqvlo8']
[2025-03-24T12:04:10.452+0000] {standard_task_runner.py:88} INFO - Job 66: Subtask reset_data
[2025-03-24T12:04:10.466+0000] {warnings.py:109} WARNING - /home/***/.local/lib/python3.8/site-packages/***/settings.py:194: DeprecationWarning: The sql_alchemy_conn option in [core] has been moved to the sql_alchemy_conn option in [database] - the old setting has been used, but please update your config.
  SQL_ALCHEMY_CONN = conf.get("database", "SQL_ALCHEMY_CONN")

[2025-03-24T12:04:10.503+0000] {task_command.py:423} INFO - Running <TaskInstance: data_service.reset_data manual__2025-03-24T12:04:06.950635+00:00 [running]> on host 4d081b2ab468
[2025-03-24T12:04:10.582+0000] {taskinstance.py:2480} INFO - Exporting env vars: AIRFLOW_CTX_DAG_OWNER='***' AIRFLOW_CTX_DAG_ID='data_service' AIRFLOW_CTX_TASK_ID='reset_data' AIRFLOW_CTX_EXECUTION_DATE='2025-03-24T12:04:06.950635+00:00' AIRFLOW_CTX_TRY_NUMBER='1' AIRFLOW_CTX_DAG_RUN_ID='manual__2025-03-24T12:04:06.950635+00:00'
[2025-03-24T12:04:10.653+0000] {docker.py:359} INFO - Starting docker container from image reset_data:latest
[2025-03-24T12:04:10.666+0000] {docker.py:367} WARNING - Using remote engine or docker-in-docker and mounting temporary volume from host is not supported. Falling back to `mount_tmp_dir=False` mode. You can set `mount_tmp_dir` parameter to False to disable mounting and remove the warning
[2025-03-24T12:04:16.288+0000] {docker.py:429} INFO - Current data replaced by raw data
[2025-03-24T12:04:16.844+0000] {taskinstance.py:1138} INFO - Marking task as SUCCESS. dag_id=data_service, task_id=reset_data, execution_date=20250324T120406, start_date=20250324T120410, end_date=20250324T120416
[2025-03-24T12:04:16.870+0000] {local_task_job_runner.py:234} INFO - Task exited with return code 0
[2025-03-24T12:04:16.890+0000] {taskinstance.py:3280} INFO - 1 downstream tasks scheduled from follow-on schedule check
